Workbook

Sheet 【指定様式】事業計画書（その3）
A1: 【指定様式】事業計画書（その３）
B2: 事業者名
B3: 株式会社ＪＴＣ
B4: 本事業計画における会社全体の事業計画（数値計画）を記載してください。
A5: 記載数値：「省力化指数」「付加価値額」「労働生産性」「1人当たり給与支給総額」「投資回収期間」
B7: 【１】省力化指数
B8: ='（別紙１）省力化計算シート'!M3 -> 0.57142857
B9: ※「（別紙１）省力化計算シート」より算出。
B10: ※「（別紙２）省力化業務プロセス図」も作成し省力化指数の詳細を説明してください。
B12: 【２】会社全体の事業計画（表）
B53: 【事業計画年数（３～５年）】
B54: 3 | D54: 年
B56: 【算定根拠】算定の根拠となる計算式等をそれぞれ記載ください。
B57: また、計画最終年の年平均成長率を転記してください。（事業者の目標値となります。）
B59: ①付加価値額 | H59: 最終年の年平均成長率 | I59: 19.04 | J59: ％
B60: 基準年度（2025年10月期）：営業利益156,038,526円＋人件費120,155,910円＋減価償却費22,704,796円＝298,899,232円 3年目（2030年10月期）：営業利益332,563,031円＋人件費145,161,000円＋減価償却費26,593,296円＝504,317,327円 年平均成長率＝{(504,317,327÷298,899,232)^(1÷3)－1}×100＝19.04％
B65: ②労働生産性 | H65: 最終年の年平均成長率 | I65: 5.99 | J65: ％
B66: 基準年度（2025年10月期）：298,899,232円÷（役員2人＋常勤従業員10人＝12人）＝24,908,269.33円／人 3年目（2030年10月期）：504,317,327円÷（役員2人＋常勤従業員15人＝17人）＝29,665,725.11円／人 年平均成長率＝{(29,665,725.11÷24,908,269.33)^(1÷3)－1}×100＝5.99％
B72: ③1人当たり給与支給総額 | H72: 最終年の年平均成長率 | I72: 3.5 | J72: ％
B73: 基準年度（2025年10月期）：36,625,814円÷8人＝4,578,226.75円／人 ※全月分の給与等の支給を受けた従業員数。期中採用者は算定対象外。 3年目（2030年10月期）：76,140,000円÷15人＝5,076,000.00円／人 年平均成長率＝{(5,076,000.00÷4,578,226.75)^(1÷3)－1}×100＝3.50％
B78: 【３】投資回収期間
B79: ='（別紙３）投資回収期間計算シート'!C3 -> 0.17871437 | D79: 年
B80: ※「（別紙３）投資回収期間計算シート」より算出（自動反映）。

Sheet （別紙１）省力化計算シート
B1: （別紙１）省力化計算シート
C3: 設備導入により削減される 業務に要していた時間 | D3: =(SUMIF(C11:C40,"<>",D11:D40)-SUMIF(E11:E40,"<>-",D11:D40)-SUMIF(F11:F40,"<0"))/60 -> 7 | G3: 時間 | I3: 設備導入後に発生する 業務に要する時間 | J3: =(SUMIF(I11:I40,"<>",J11:J40)-SUMIF(N11:N40,"<>-",J11:J40)+SUMIF(N11:N40,">0"))/60 -> 3 | K3: 時間 | L3: 省力化指数 | M3: =IF(D3=0,0,IF((D3-J3)/D3<0,0,(D3-J3)/D3)) -> 0.57142857
B5: ■設備導入前の業務プロセス・作業工程 | H5: ■設備導入後の業務プロセス・作業工程
C7: 設備導入前の作業時間合計 | D7: =SUMIF(C11:C40,"<>",D11:D40)/60 -> 8 | G7: 時間 | I7: 設備導入後の作業時間合計 | J7: =SUMIF(I11:I40,"<>",J11:J40)/60 -> 4 | K7: 時間
B10: No. | C10: 工程名・作業名 | D10: 作業時間（分） | E10: 対応する導入後の 業務プロセスNo | F10: 同工程差分時間（分） | H10: No. | I10: 工程名・作業名 | J10: 作業時間（分） | K10: 作業種別 | L10: 対応する設備導入前の 業務プロセスNo. | N10: 同工程差分時間（分） | P10: 作業種別選択肢
B11: 1 | C11: 部材運搬・段取り | D11: 60 | E11: =IF(OR(C11="",D11=""),"-",IF(IFERROR(MATCH(B11,L$11:L$40,0),"")="","-",IF(OR(INDEX(I$11:I$40,MATCH(B11,L$11:L$40,0))="",INDEX(J$11:J$40,MATCH(B11,L$11:L$40,0))="",INDEX(K$11:K$40,MATCH(B11,L$11:L$40,0))<>"内容は変化しない作業"),"-",MATCH(B11,L$11:L$40,0)))) -> - | F11: {=IF(E11="-","-",IF(AND(C11<>"",D11>0,INDEX(K$11:K$40,E11)="内容は変化しない作業",AND(E11<>"-",E11<>""),INDEX(I$11:I$40,E11)<>"",INDEX(J$11:J$40,E11)<>""),INDEX(J$11:J$40,E11)-D11,"-"))} -> - | H11: 1 | I11: コンベア投入・部材セット | J11: 60 | K11: 新たに追加される作業 | L11: 2 | N11: {=IF(AND(I11<>"",J11>0,K11="内容は変化しない作業",L11>0,INDEX(C$11:C$40,L11)<>"",INDEX(D$11:D$40,L11)<>""),J11-INDEX(D$11:D$40,L11),"-")} -> - | P11: 新たに追加される作業
B12: 2 | C12: 手作業ケレン（電動工具・ワイヤーブラシ） | D12: 360 | E12: =IF(OR(C12="",D12=""),"-",IF(IFERROR(MATCH(B12,L$11:L$40,0),"")="","-",IF(OR(INDEX(I$11:I$40,MATCH(B12,L$11:L$40,0))="",INDEX(J$11:J$40,MATCH(B12,L$11:L$40,0))="",INDEX(K$11:K$40,MATCH(B12,L$11:L$40,0))<>"内容は変化しない作業"),"-",MATCH(B12,L$11:L$40,0)))) -> - | F12: {=IF(E12="-","-",IF(AND(C12<>"",D12>0,INDEX(K$11:K$40,E12)="内容は変化しない作業",AND(E12<>"-",E12<>""),INDEX(I$11:I$40,E12)<>"",INDEX(J$11:J$40,E12)<>""),INDEX(J$11:J$40,E12)-D12,"-"))} -> - | H12: 2 | I12: ブラスト処理条件設定・監視 | J12: 120 | K12: 新たに追加される作業 | L12: 2 | N12: {=IF(AND(I12<>"",J12>0,K12="内容は変化しない作業",L12>0,INDEX(C$11:C$40,L12)<>"",INDEX(D$11:D$40,L12)<>""),J12-INDEX(D$11:D$40,L12),"-")} -> - | P12: 内容は変化しない作業
B13: 3 | C13: 取出し・仕上がり確認・在庫区分 | D13: 60 | E13: =IF(OR(C13="",D13=""),"-",IF(IFERROR(MATCH(B13,L$11:L$40,0),"")="","-",IF(OR(INDEX(I$11:I$40,MATCH(B13,L$11:L$40,0))="",INDEX(J$11:J$40,MATCH(B13,L$11:L$40,0))="",INDEX(K$11:K$40,MATCH(B13,L$11:L$40,0))<>"内容は変化しない作業"),"-",MATCH(B13,L$11:L$40,0)))) -> 3 | F13: {=IF(E13="-","-",IF(AND(C13<>"",D13>0,INDEX(K$11:K$40,E13)="内容は変化しない作業",AND(E13<>"-",E13<>""),INDEX(I$11:I$40,E13)<>"",INDEX(J$11:J$40,E13)<>""),INDEX(J$11:J$40,E13)-D13,"-"))} -> 0 | H13: 3 | I13: 取出し・仕上がり確認・在庫区分 | J13: 60 | K13: 内容は変化しない作業 | L13: 3 | N13: {=IF(AND(I13<>"",J13>0,K13="内容は変化しない作業",L13>0,INDEX(C$11:C$40,L13)<>"",INDEX(D$11:D$40,L13)<>""),J13-INDEX(D$11:D$40,L13),"-")} -> 0
B14: 4 | E14: =IF(OR(C14="",D14=""),"-",IF(IFERROR(MATCH(B14,L$11:L$40,0),"")="","-",IF(OR(INDEX(I$11:I$40,MATCH(B14,L$11:L$40,0))="",INDEX(J$11:J$40,MATCH(B14,L$11:L$40,0))="",INDEX(K$11:K$40,MATCH(B14,L$11:L$40,0))<>"内容は変化しない作業"),"-",MATCH(B14,L$11:L$40,0)))) -> - | F14: {=IF(E14="-","-",IF(AND(C14<>"",D14>0,INDEX(K$11:K$40,E14)="内容は変化しない作業",AND(E14<>"-",E14<>""),INDEX(I$11:I$40,E14)<>"",INDEX(J$11:J$40,E14)<>""),INDEX(J$11:J$40,E14)-D14,"-"))} -> - | H14: 4 | N14: {=IF(AND(I14<>"",J14>0,K14="内容は変化しない作業",L14>0,INDEX(C$11:C$40,L14)<>"",INDEX(D$11:D$40,L14)<>""),J14-INDEX(D$11:D$40,L14),"-")} -> -
B15: 5 | E15: =IF(OR(C15="",D15=""),"-",IF(IFERROR(MATCH(B15,L$11:L$40,0),"")="","-",IF(OR(INDEX(I$11:I$40,MATCH(B15,L$11:L$40,0))="",INDEX(J$11:J$40,MATCH(B15,L$11:L$40,0))="",INDEX(K$11:K$40,MATCH(B15,L$11:L$40,0))<>"内容は変化しない作業"),"-",MATCH(B15,L$11:L$40,0)))) -> - | F15: {=IF(E15="-","-",IF(AND(C15<>"",D15>0,INDEX(K$11:K$40,E15)="内容は変化しない作業",AND(E15<>"-",E15<>""),INDEX(I$11:I$40,E15)<>"",INDEX(J$11:J$40,E15)<>""),INDEX(J$11:J$40,E15)-D15,"-"))} -> - | H15: 5 | N15: {=IF(AND(I15<>"",J15>0,K15="内容は変化しない作業",L15>0,INDEX(C$11:C$40,L15)<>"",INDEX(D$11:D$40,L15)<>""),J15-INDEX(D$11:D$40,L15),"-")} -> -
B16: 6 | E16: =IF(OR(C16="",D16=""),"-",IF(IFERROR(MATCH(B16,L$11:L$40,0),"")="","-",IF(OR(INDEX(I$11:I$40,MATCH(B16,L$11:L$40,0))="",INDEX(J$11:J$40,MATCH(B16,L$11:L$40,0))="",INDEX(K$11:K$40,MATCH(B16,L$11:L$40,0))<>"内容は変化しない作業"),"-",MATCH(B16,L$11:L$40,0)))) -> - | F16: {=IF(E16="-","-",IF(AND(C16<>"",D16>0,INDEX(K$11:K$40,E16)="内容は変化しない作業",AND(E16<>"-",E16<>""),INDEX(I$11:I$40,E16)<>"",INDEX(J$11:J$40,E16)<>""),INDEX(J$11:J$40,E16)-D16,"-"))} -> - | H16: 6 | N16: {=IF(AND(I16<>"",J16>0,K16="内容は変化しない作業",L16>0,INDEX(C$11:C$40,L16)<>"",INDEX(D$11:D$40,L16)<>""),J16-INDEX(D$11:D$40,L16),"-")} -> -
B17: 7 | E17: =IF(OR(C17="",D17=""),"-",IF(IFERROR(MATCH(B17,L$11:L$40,0),"")="","-",IF(OR(INDEX(I$11:I$40,MATCH(B17,L$11:L$40,0))="",INDEX(J$11:J$40,MATCH(B17,L$11:L$40,0))="",INDEX(K$11:K$40,MATCH(B17,L$11:L$40,0))<>"内容は変化しない作業"),"-",MATCH(B17,L$11:L$40,0)))) -> - | F17: {=IF(E17="-","-",IF(AND(C17<>"",D17>0,INDEX(K$11:K$40,E17)="内容は変化しない作業",AND(E17<>"-",E17<>""),INDEX(I$11:I$40,E17)<>"",INDEX(J$11:J$40,E17)<>""),INDEX(J$11:J$40,E17)-D17,"-"))} -> - | H17: 7 | N17: {=IF(AND(I17<>"",J17>0,K17="内容は変化しない作業",L17>0,INDEX(C$11:C$40,L17)<>"",INDEX(D$11:D$40,L17)<>""),J17-INDEX(D$11:D$40,L17),"-")} -> -
B18: 8 | E18: =IF(OR(C18="",D18=""),"-",IF(IFERROR(MATCH(B18,L$11:L$40,0),"")="","-",IF(OR(INDEX(I$11:I$40,MATCH(B18,L$11:L$40,0))="",INDEX(J$11:J$40,MATCH(B18,L$11:L$40,0))="",INDEX(K$11:K$40,MATCH(B18,L$11:L$40,0))<>"内容は変化しない作業"),"-",MATCH(B18,L$11:L$40,0)))) -> - | F18: {=IF(E18="-","-",IF(AND(C18<>"",D18>0,INDEX(K$11:K$40,E18)="内容は変化しない作業",AND(E18<>"-",E18<>""),INDEX(I$11:I$40,E18)<>"",INDEX(J$11:J$40,E18)<>""),INDEX(J$11:J$40,E18)-D18,"-"))} -> - | H18: 8 | N18: {=IF(AND(I18<>"",J18>0,K18="内容は変化しない作業",L18>0,INDEX(C$11:C$40,L18)<>"",INDEX(D$11:D$40,L18)<>""),J18-INDEX(D$11:D$40,L18),"-")} -> -
B19: 9 | E19: =IF(OR(C19="",D19=""),"-",IF(IFERROR(MATCH(B19,L$11:L$40,0),"")="","-",IF(OR(INDEX(I$11:I$40,MATCH(B19,L$11:L$40,0))="",INDEX(J$11:J$40,MATCH(B19,L$11:L$40,0))="",INDEX(K$11:K$40,MATCH(B19,L$11:L$40,0))<>"内容は変化しない作業"),"-",MATCH(B19,L$11:L$40,0)))) -> - | F19: {=IF(E19="-","-",IF(AND(C19<>"",D19>0,INDEX(K$11:K$40,E19)="内容は変化しない作業",AND(E19<>"-",E19<>""),INDEX(I$11:I$40,E19)<>"",INDEX(J$11:J$40,E19)<>""),INDEX(J$11:J$40,E19)-D19,"-"))} -> - | H19: 9 | N19: {=IF(AND(I19<>"",J19>0,K19="内容は変化しない作業",L19>0,INDEX(C$11:C$40,L19)<>"",INDEX(D$11:D$40,L19)<>""),J19-INDEX(D$11:D$40,L19),"-")} -> -
B20: 10 | E20: =IF(OR(C20="",D20=""),"-",IF(IFERROR(MATCH(B20,L$11:L$40,0),"")="","-",IF(OR(INDEX(I$11:I$40,MATCH(B20,L$11:L$40,0))="",INDEX(J$11:J$40,MATCH(B20,L$11:L$40,0))="",INDEX(K$11:K$40,MATCH(B20,L$11:L$40,0))<>"内容は変化しない作業"),"-",MATCH(B20,L$11:L$40,0)))) -> - | F20: {=IF(E20="-","-",IF(AND(C20<>"",D20>0,INDEX(K$11:K$40,E20)="内容は変化しない作業",AND(E20<>"-",E20<>""),INDEX(I$11:I$40,E20)<>"",INDEX(J$11:J$40,E20)<>""),INDEX(J$11:J$40,E20)-D20,"-"))} -> - | H20: 10 | N20: {=IF(AND(I20<>"",J20>0,K20="内容は変化しない作業",L20>0,INDEX(C$11:C$40,L20)<>"",INDEX(D$11:D$40,L20)<>""),J20-INDEX(D$11:D$40,L20),"-")} -> -
B21: 11 | E21: =IF(OR(C21="",D21=""),"-",IF(IFERROR(MATCH(B21,L$11:L$40,0),"")="","-",IF(OR(INDEX(I$11:I$40,MATCH(B21,L$11:L$40,0))="",INDEX(J$11:J$40,MATCH(B21,L$11:L$40,0))="",INDEX(K$11:K$40,MATCH(B21,L$11:L$40,0))<>"内容は変化しない作業"),"-",MATCH(B21,L$11:L$40,0)))) -> - | F21: {=IF(E21="-","-",IF(AND(C21<>"",D21>0,INDEX(K$11:K$40,E21)="内容は変化しない作業",AND(E21<>"-",E21<>""),INDEX(I$11:I$40,E21)<>"",INDEX(J$11:J$40,E21)<>""),INDEX(J$11:J$40,E21)-D21,"-"))} -> - | H21: 11 | N21: {=IF(AND(I21<>"",J21>0,K21="内容は変化しない作業",L21>0,INDEX(C$11:C$40,L21)<>"",INDEX(D$11:D$40,L21)<>""),J21-INDEX(D$11:D$40,L21),"-")} -> -
B22: 12 | E22: =IF(OR(C22="",D22=""),"-",IF(IFERROR(MATCH(B22,L$11:L$40,0),"")="","-",IF(OR(INDEX(I$11:I$40,MATCH(B22,L$11:L$40,0))="",INDEX(J$11:J$40,MATCH(B22,L$11:L$40,0))="",INDEX(K$11:K$40,MATCH(B22,L$11:L$40,0))<>"内容は変化しない作業"),"-",MATCH(B22,L$11:L$40,0)))) -> - | F22: {=IF(E22="-","-",IF(AND(C22<>"",D22>0,INDEX(K$11:K$40,E22)="内容は変化しない作業",AND(E22<>"-",E22<>""),INDEX(I$11:I$40,E22)<>"",INDEX(J$11:J$40,E22)<>""),INDEX(J$11:J$40,E22)-D22,"-"))} -> - | H22: 12 | N22: {=IF(AND(I22<>"",J22>0,K22="内容は変化しない作業",L22>0,INDEX(C$11:C$40,L22)<>"",INDEX(D$11:D$40,L22)<>""),J22-INDEX(D$11:D$40,L22),"-")} -> -
B23: 13 | E23: =IF(OR(C23="",D23=""),"-",IF(IFERROR(MATCH(B23,L$11:L$40,0),"")="","-",IF(OR(INDEX(I$11:I$40,MATCH(B23,L$11:L$40,0))="",INDEX(J$11:J$40,MATCH(B23,L$11:L$40,0))="",INDEX(K$11:K$40,MATCH(B23,L$11:L$40,0))<>"内容は変化しない作業"),"-",MATCH(B23,L$11:L$40,0)))) -> - | F23: {=IF(E23="-","-",IF(AND(C23<>"",D23>0,INDEX(K$11:K$40,E23)="内容は変化しない作業",AND(E23<>"-",E23<>""),INDEX(I$11:I$40,E23)<>"",INDEX(J$11:J$40,E23)<>""),INDEX(J$11:J$40,E23)-D23,"-"))} -> - | H23: 13 | N23: {=IF(AND(I23<>"",J23>0,K23="内容は変化しない作業",L23>0,INDEX(C$11:C$40,L23)<>"",INDEX(D$11:D$40,L23)<>""),J23-INDEX(D$11:D$40,L23),"-")} -> -
B24: 14 | E24: =IF(OR(C24="",D24=""),"-",IF(IFERROR(MATCH(B24,L$11:L$40,0),"")="","-",IF(OR(INDEX(I$11:I$40,MATCH(B24,L$11:L$40,0))="",INDEX(J$11:J$40,MATCH(B24,L$11:L$40,0))="",INDEX(K$11:K$40,MATCH(B24,L$11:L$40,0))<>"内容は変化しない作業"),"-",MATCH(B24,L$11:L$40,0)))) -> - | F24: {=IF(E24="-","-",IF(AND(C24<>"",D24>0,INDEX(K$11:K$40,E24)="内容は変化しない作業",AND(E24<>"-",E24<>""),INDEX(I$11:I$40,E24)<>"",INDEX(J$11:J$40,E24)<>""),INDEX(J$11:J$40,E24)-D24,"-"))} -> - | H24: 14 | N24: {=IF(AND(I24<>"",J24>0,K24="内容は変化しない作業",L24>0,INDEX(C$11:C$40,L24)<>"",INDEX(D$11:D$40,L24)<>""),J24-INDEX(D$11:D$40,L24),"-")} -> -
B25: 15 | E25: =IF(OR(C25="",D25=""),"-",IF(IFERROR(MATCH(B25,L$11:L$40,0),"")="","-",IF(OR(INDEX(I$11:I$40,MATCH(B25,L$11:L$40,0))="",INDEX(J$11:J$40,MATCH(B25,L$11:L$40,0))="",INDEX(K$11:K$40,MATCH(B25,L$11:L$40,0))<>"内容は変化しない作業"),"-",MATCH(B25,L$11:L$40,0)))) -> - | F25: {=IF(E25="-","-",IF(AND(C25<>"",D25>0,INDEX(K$11:K$40,E25)="内容は変化しない作業",AND(E25<>"-",E25<>""),INDEX(I$11:I$40,E25)<>"",INDEX(J$11:J$40,E25)<>""),INDEX(J$11:J$40,E25)-D25,"-"))} -> - | H25: 15 | N25: {=IF(AND(I25<>"",J25>0,K25="内容は変化しない作業",L25>0,INDEX(C$11:C$40,L25)<>"",INDEX(D$11:D$40,L25)<>""),J25-INDEX(D$11:D$40,L25),"-")} -> -
... B40: 30 | E40: =IF(OR(C40="",D40=""),"-",IF(IFERROR(MATCH(B40,L$11:L$40,0),"")="","-",IF(OR(INDEX(I$11:I$40,MATCH(B40,L$11:L$40,0))="",INDEX(J$11:J$40,MATCH(B40,L$11:L$40,0))="",INDEX(K$11:K$40,MATCH(B40,L$11:L$40,0))<>"内容は変化しない作業"),"-",MATCH(B40,L$11:L$40,0)))) -> - | F40: {=IF(E40="-","-",IF(AND(C40<>"",D40>0,INDEX(K$11:K$40,E40)="内容は変化しない作業",AND(E40<>"-",E40<>""),INDEX(I$11:I$40,E40)<>"",INDEX(J$11:J$40,E40)<>""),INDEX(J$11:J$40,E40)-D40,"-"))} -> - | H40: 30 | N40: {=IF(AND(I40<>"",J40>0,K40="内容は変化しない作業",L40>0,INDEX(C$11:C$40,L40)<>"",INDEX(D$11:D$40,L40)<>""),J40-INDEX(D$11:D$40,L40),"-")} -> -

Sheet （別紙２）省力化業務プロセス図
B1: （別紙２）省力化業務プロセス図 ※（別紙1）で入れた業務プロセス・作業工程がフロー図として表示されます。
O3: 省力化指数 | S3: ='（別紙１）省力化計算シート'!M3 -> 0.57142857
C5: ■設備導入前の業務プロセス・作業工程 （BEFORE） | O5: 設備導入による削減時間 | S5: ='（別紙１）省力化計算シート'!D3 -> 7 | T5: 時間
C8: ='（別紙１）省力化計算シート'!C11 -> 部材運搬・段取り | E8: > | G8: ='（別紙１）省力化計算シート'!C12 -> 手作業ケレン（電動工具・ワイヤーブラシ） | I8: > | K8: ='（別紙１）省力化計算シート'!C13 -> 取出し・仕上がり確認・在庫区分 | M8: > | O8: ='（別紙１）省力化計算シート'!C14 -> 0 | Q8: > | S8: ='（別紙１）省力化計算シート'!C15 -> 0 | U8: > | X8: 削減される作業
C9: =IF('（別紙１）省力化計算シート'!D11="","",IF(OR('（別紙１）省力化計算シート'!F11="-",'（別紙１）省力化計算シート'!F11=0),'（別紙１）省力化計算シート'!D11&"分",'（別紙１）省力化計算シート'!D11&"分"&" (→"&'（別紙１）省力化計算シート'!D11+'（別紙１）省力化計算シート'!F11&"分）")) -> 60分 | G9: =IF('（別紙１）省力化計算シート'!D12="","",IF(OR('（別紙１）省力化計算シート'!F12="-",'（別紙１）省力化計算シート'!F12=0),'（別紙１）省力化計算シート'!D12&"分",'（別紙１）省力化計算シート'!D12&"分"&" (→"&'（別紙１）省力化計算シート'!D12+'（別紙１）省力化計算シート'!F12&"分）")) -> 360分 | K9: =IF('（別紙１）省力化計算シート'!D13="","",IF(OR('（別紙１）省力化計算シート'!F13="-",'（別紙１）省力化計算シート'!F13=0),'（別紙１）省力化計算シート'!D13&"分",'（別紙１）省力化計算シート'!D13&"分"&" (→"&'（別紙１）省力化計算シート'!D13+'（別紙１）省力化計算シート'!F13&"分）")) -> 60分 | O9: =IF('（別紙１）省力化計算シート'!D14="","",IF(OR('（別紙１）省力化計算シート'!F14="-",'（別紙１）省力化計算シート'!F14=0),'（別紙１）省力化計算シート'!D14&"分",'（別紙１）省力化計算シート'!D14&"分"&" (→"&'（別紙１）省力化計算シート'!D14+'（別紙１）省力化計算シート'!F14&"分）")) | S9: =IF('（別紙１）省力化計算シート'!D15="","",IF(OR('（別紙１）省力化計算シート'!F15="-",'（別紙１）省力化計算シート'!F15=0),'（別紙１）省力化計算シート'!D15&"分",'（別紙１）省力化計算シート'!D15&"分"&" (→"&'（別紙１）省力化計算シート'!D15+'（別紙１）省力化計算シート'!F15&"分）"))
C10: 対象部材を運搬し、種類・寸法・汚れ別に選別 | G10: 泥・塗料・コンクリート片・錆等を手作業で除去 | K10: 処理状態を確認し、販売・補修・廃棄に区分
X11: 時間が削減される作業
C15: ='（別紙１）省力化計算シート'!C16 -> 0 | E15: > | G15: ='（別紙１）省力化計算シート'!C17 -> 0 | I15: > | K15: ='（別紙１）省力化計算シート'!C18 -> 0 | M15: > | O15: ='（別紙１）省力化計算シート'!C19 -> 0 | Q15: > | S15: ='（別紙１）省力化計算シート'!C20 -> 0 | U15: > | X15: 導入前後で同様の作業
C16: =IF('（別紙１）省力化計算シート'!D16="","",IF(OR('（別紙１）省力化計算シート'!F16="-",'（別紙１）省力化計算シート'!F16=0),'（別紙１）省力化計算シート'!D16&"分",'（別紙１）省力化計算シート'!D16&"分"&" (→"&'（別紙１）省力化計算シート'!D16+'（別紙１）省力化計算シート'!F16&"分）")) | G16: =IF('（別紙１）省力化計算シート'!D17="","",IF(OR('（別紙１）省力化計算シート'!F17="-",'（別紙１）省力化計算シート'!F17=0),'（別紙１）省力化計算シート'!D17&"分",'（別紙１）省力化計算シート'!D17&"分"&" (→"&'（別紙１）省力化計算シート'!D17+'（別紙１）省力化計算シート'!F17&"分）")) | K16: =IF('（別紙１）省力化計算シート'!D18="","",IF(OR('（別紙１）省力化計算シート'!F18="-",'（別紙１）省力化計算シート'!F18=0),'（別紙１）省力化計算シート'!D18&"分",'（別紙１）省力化計算シート'!D18&"分"&" (→"&'（別紙１）省力化計算シート'!D18+'（別紙１）省力化計算シート'!F18&"分）")) | O16: =IF('（別紙１）省力化計算シート'!D19="","",IF(OR('（別紙１）省力化計算シート'!F19="-",'（別紙１）省力化計算シート'!F19=0),'（別紙１）省力化計算シート'!D19&"分",'（別紙１）省力化計算シート'!D19&"分"&" (→"&'（別紙１）省力化計算シート'!D19+'（別紙１）省力化計算シート'!F19&"分）")) | S16: =IF('（別紙１）省力化計算シート'!D20="","",IF(OR('（別紙１）省力化計算シート'!F20="-",'（別紙１）省力化計算シート'!F20=0),'（別紙１）省力化計算シート'!D20&"分",'（別紙１）省力化計算シート'!D20&"分"&" (→"&'（別紙１）省力化計算シート'!D20+'（別紙１）省力化計算シート'!F20&"分）"))
X17: 作業内容の説明 入力欄
C22: ='（別紙１）省力化計算シート'!C21 -> 0 | E22: > | G22: ='（別紙１）省力化計算シート'!C22 -> 0 | I22: > | K22: ='（別紙１）省力化計算シート'!C23 -> 0 | M22: > | O22: ='（別紙１）省力化計算シート'!C24 -> 0 | Q22: > | S22: ='（別紙１）省力化計算シート'!C25 -> 0 | U22: >
C23: =IF('（別紙１）省力化計算シート'!D21="","",IF(OR('（別紙１）省力化計算シート'!F21="-",'（別紙１）省力化計算シート'!F21=0),'（別紙１）省力化計算シート'!D21&"分",'（別紙１）省力化計算シート'!D21&"分"&" (→"&'（別紙１）省力化計算シート'!D21+'（別紙１）省力化計算シート'!F21&"分）")) | G23: =IF('（別紙１）省力化計算シート'!D22="","",IF(OR('（別紙１）省力化計算シート'!F22="-",'（別紙１）省力化計算シート'!F22=0),'（別紙１）省力化計算シート'!D22&"分",'（別紙１）省力化計算シート'!D22&"分"&" (→"&'（別紙１）省力化計算シート'!D22+'（別紙１）省力化計算シート'!F22&"分）")) | K23: =IF('（別紙１）省力化計算シート'!D23="","",IF(OR('（別紙１）省力化計算シート'!F23="-",'（別紙１）省力化計算シート'!F23=0),'（別紙１）省力化計算シート'!D23&"分",'（別紙１）省力化計算シート'!D23&"分"&" (→"&'（別紙１）省力化計算シート'!D23+'（別紙１）省力化計算シート'!F23&"分）")) | O23: =IF('（別紙１）省力化計算シート'!D24="","",IF(OR('（別紙１）省力化計算シート'!F24="-",'（別紙１）省力化計算シート'!F24=0),'（別紙１）省力化計算シート'!D24&"分",'（別紙１）省力化計算シート'!D24&"分"&" (→"&'（別紙１）省力化計算シート'!D24+'（別紙１）省力化計算シート'!F24&"分）")) | S23: =IF('（別紙１）省力化計算シート'!D25="","",IF(OR('（別紙１）省力化計算シート'!F25="-",'（別紙１）省力化計算シート'!F25=0),'（別紙１）省力化計算シート'!D25&"分",'（別紙１）省力化計算シート'!D25&"分"&" (→"&'（別紙１）省力化計算シート'!D25+'（別紙１）省力化計算シート'!F25&"分）"))
C29: ='（別紙１）省力化計算シート'!C26 -> 0 | E29: > | G29: ='（別紙１）省力化計算シート'!C27 -> 0 | I29: > | K29: ='（別紙１）省力化計算シート'!C28 -> 0 | M29: > | O29: ='（別紙１）省力化計算シート'!C29 -> 0 | Q29: > | S29: ='（別紙１）省力化計算シート'!C30 -> 0 | U29: >
C30: =IF('（別紙１）省力化計算シート'!D26="","",IF(OR('（別紙１）省力化計算シート'!F26="-",'（別紙１）省力化計算シート'!F26=0),'（別紙１）省力化計算シート'!D26&"分",'（別紙１）省力化計算シート'!D26&"分"&" (→"&'（別紙１）省力化計算シート'!D26+'（別紙１）省力化計算シート'!F26&"分）")) | G30: =IF('（別紙１）省力化計算シート'!D27="","",IF(OR('（別紙１）省力化計算シート'!F27="-",'（別紙１）省力化計算シート'!F27=0),'（別紙１）省力化計算シート'!D27&"分",'（別紙１）省力化計算シート'!D27&"分"&" (→"&'（別紙１）省力化計算シート'!D27+'（別紙１）省力化計算シート'!F27&"分）")) | K30: =IF('（別紙１）省力化計算シート'!D28="","",IF(OR('（別紙１）省力化計算シート'!F28="-",'（別紙１）省力化計算シート'!F28=0),'（別紙１）省力化計算シート'!D28&"分",'（別紙１）省力化計算シート'!D28&"分"&" (→"&'（別紙１）省力化計算シート'!D28+'（別紙１）省力化計算シート'!F28&"分）")) | O30: =IF('（別紙１）省力化計算シート'!D29="","",IF(OR('（別紙１）省力化計算シート'!F29="-",'（別紙１）省力化計算シート'!F29=0),'（別紙１）省力化計算シート'!D29&"分",'（別紙１）省力化計算シート'!D29&"分"&" (→"&'（別紙１）省力化計算シート'!D29+'（別紙１）省力化計算シート'!F29&"分）")) | S30: =IF('（別紙１）省力化計算シート'!D30="","",IF(OR('（別紙１）省力化計算シート'!F30="-",'（別紙１）省力化計算シート'!F30=0),'（別紙１）省力化計算シート'!D30&"分",'（別紙１）省力化計算シート'!D30&"分"&" (→"&'（別紙１）省力化計算シート'!D30+'（別紙１）省力化計算シート'!F30&"分）"))
C36: ='（別紙１）省力化計算シート'!C31 -> 0 | E36: > | G36: ='（別紙１）省力化計算シート'!C32 -> 0 | I36: > | K36: ='（別紙１）省力化計算シート'!C33 -> 0 | M36: > | O36: ='（別紙１）省力化計算シート'!C34 -> 0 | Q36: > | S36: ='（別紙１）省力化計算シート'!C35 -> 0 | U36: >
C37: =IF('（別紙１）省力化計算シート'!D31="","",IF(OR('（別紙１）省力化計算シート'!F31="-",'（別紙１）省力化計算シート'!F31=0),'（別紙１）省力化計算シート'!D31&"分",'（別紙１）省力化計算シート'!D31&"分"&" (→"&'（別紙１）省力化計算シート'!D31+'（別紙１）省力化計算シート'!F31&"分）")) | G37: =IF('（別紙１）省力化計算シート'!D32="","",IF(OR('（別紙１）省力化計算シート'!F32="-",'（別紙１）省力化計算シート'!F32=0),'（別紙１）省力化計算シート'!D32&"分",'（別紙１）省力化計算シート'!D32&"分"&" (→"&'（別紙１）省力化計算シート'!D32+'（別紙１）省力化計算シート'!F32&"分）")) | K37: =IF('（別紙１）省力化計算シート'!D33="","",IF(OR('（別紙１）省力化計算シート'!F33="-",'（別紙１）省力化計算シート'!F33=0),'（別紙１）省力化計算シート'!D33&"分",'（別紙１）省力化計算シート'!D33&"分"&" (→"&'（別紙１）省力化計算シート'!D33+'（別紙１）省力化計算シート'!F33&"分）")) | O37: =IF('（別紙１）省力化計算シート'!D34="","",IF(OR('（別紙１）省力化計算シート'!F34="-",'（別紙１）省力化計算シート'!F34=0),'（別紙１）省力化計算シート'!D34&"分",'（別紙１）省力化計算シート'!D34&"分"&" (→"&'（別紙１）省力化計算シート'!D34+'（別紙１）省力化計算シート'!F34&"分）")) | S37: =IF('（別紙１）省力化計算シート'!D35="","",IF(OR('（別紙１）省力化計算シート'!F35="-",'（別紙１）省力化計算シート'!F35=0),'（別紙１）省力化計算シート'!D35&"分",'（別紙１）省力化計算シート'!D35&"分"&" (→"&'（別紙１）省力化計算シート'!D35+'（別紙１）省力化計算シート'!F35&"分）"))
C43: ='（別紙１）省力化計算シート'!C36 -> 0 | E43: > | G43: ='（別紙１）省力化計算シート'!C37 -> 0 | I43: > | K43: ='（別紙１）省力化計算シート'!C38 -> 0 | M43: > | O43: ='（別紙１）省力化計算シート'!C39 -> 0 | Q43: > | S43: ='（別紙１）省力化計算シート'!C40 -> 0
C44: =IF('（別紙１）省力化計算シート'!D36="","",IF(OR('（別紙１）省力化計算シート'!F36="-",'（別紙１）省力化計算シート'!F36=0),'（別紙１）省力化計算シート'!D36&"分",'（別紙１）省力化計算シート'!D36&"分"&" (→"&'（別紙１）省力化計算シート'!D36+'（別紙１）省力化計算シート'!F36&"分）")) | G44: =IF('（別紙１）省力化計算シート'!D37="","",IF(OR('（別紙１）省力化計算シート'!F37="-",'（別紙１）省力化計算シート'!F37=0),'（別紙１）省力化計算シート'!D37&"分",'（別紙１）省力化計算シート'!D37&"分"&" (→"&'（別紙１）省力化計算シート'!D37+'（別紙１）省力化計算シート'!F37&"分）")) | K44: =IF('（別紙１）省力化計算シート'!D38="","",IF(OR('（別紙１）省力化計算シート'!F38="-",'（別紙１）省力化計算シート'!F38=0),'（別紙１）省力化計算シート'!D38&"分",'（別紙１）省力化計算シート'!D38&"分"&" (→"&'（別紙１）省力化計算シート'!D38+'（別紙１）省力化計算シート'!F38&"分）")) | O44: =IF('（別紙１）省力化計算シート'!D39="","",IF(OR('（別紙１）省力化計算シート'!F39="-",'（別紙１）省力化計算シート'!F39=0),'（別紙１）省力化計算シート'!D39&"分",'（別紙１）省力化計算シート'!D39&"分"&" (→"&'（別紙１）省力化計算シート'!D39+'（別紙１）省力化計算シート'!F39&"分）")) | S44: =IF('（別紙１）省力化計算シート'!D40="","",IF(OR('（別紙１）省力化計算シート'!F40="-",'（別紙１）省力化計算シート'!F40=0),'（別紙１）省力化計算シート'!D40&"分",'（別紙１）省力化計算シート'!D40&"分"&" (→"&'（別紙１）省力化計算シート'!D40+'（別紙１）省力化計算シート'!F40&"分）"))
A48: =IF(COUNTA('（別紙１）省力化計算シート'!C26:C40)<>0,"← 非表示エリアに記載があります。[＋]をクリックして表示してください。[-]の場合は、すべて表示されています。","")
C50: ■設備導入後の業務プロセス・作業工程 （AFTER） | O50: 設備導入による増加時間 | S50: ='（別紙１）省力化計算シート'!J3 -> 3 | T50: 時間
C53: ='（別紙１）省力化計算シート'!I11 -> コンベア投入・部材セット | E53: > | G53: ='（別紙１）省力化計算シート'!I12 -> ブラスト処理条件設定・監視 | I53: > | K53: ='（別紙１）省力化計算シート'!I13 -> 取出し・仕上がり確認・在庫区分 | M53: > | O53: ='（別紙１）省力化計算シート'!I14 -> 0 | Q53: > | S53: ='（別紙１）省力化計算シート'!I15 -> 0 | U53: > | X53: 新たに追加される作業
C54: =IF('（別紙１）省力化計算シート'!J11="","",IF(OR('（別紙１）省力化計算シート'!N11="-",'（別紙１）省力化計算シート'!N11=0),'（別紙１）省力化計算シート'!J11&"分","("&'（別紙１）省力化計算シート'!J11-'（別紙１）省力化計算シート'!N11&"分→）"&'（別紙１）省力化計算シート'!J11&"分")) -> 60分 | G54: =IF('（別紙１）省力化計算シート'!J12="","",IF(OR('（別紙１）省力化計算シート'!N12="-",'（別紙１）省力化計算シート'!N12=0),'（別紙１）省力化計算シート'!J12&"分","("&'（別紙１）省力化計算シート'!J12-'（別紙１）省力化計算シート'!N12&"分→）"&'（別紙１）省力化計算シート'!J12&"分")) -> 120分 | K54: =IF('（別紙１）省力化計算シート'!J13="","",IF(OR('（別紙１）省力化計算シート'!N13="-",'（別紙１）省力化計算シート'!N13=0),'（別紙１）省力化計算シート'!J13&"分","("&'（別紙１）省力化計算シート'!J13-'（別紙１）省力化計算シート'!N13&"分→）"&'（別紙１）省力化計算シート'!J13&"分")) -> 60分 | O54: =IF('（別紙１）省力化計算シート'!J14="","",IF(OR('（別紙１）省力化計算シート'!N14="-",'（別紙１）省力化計算シート'!N14=0),'（別紙１）省力化計算シート'!J14&"分","("&'（別紙１）省力化計算シート'!J14-'（別紙１）省力化計算シート'!N14&"分→）"&'（別紙１）省力化計算シート'!J14&"分")) | S54: =IF('（別紙１）省力化計算シート'!J15="","",IF(OR('（別紙１）省力化計算シート'!N15="-",'（別紙１）省力化計算シート'!N15=0),'（別紙１）省力化計算シート'!J15&"分","("&'（別紙１）省力化計算シート'!J15-'（別紙１）省力化計算シート'!N15&"分→）"&'（別紙１）省力化計算シート'!J15&"分"))
C55: 部材を配置し、搬送ラインへ投入 | G55: 搬送速度を設定し、処理状況と設備の異常を監視 | K55: 処理状態を確認し、販売・補修・廃棄に区分
X56: 時間が増加する作業
C60: ='（別紙１）省力化計算シート'!I16 -> 0 | E60: > | G60: ='（別紙１）省力化計算シート'!I17 -> 0 | I60: > | K60: ='（別紙１）省力化計算シート'!I18 -> 0 | M60: > | O60: ='（別紙１）省力化計算シート'!I19 -> 0 | Q60: > | S60: ='（別紙１）省力化計算シート'!I20 -> 0 | U60: > | X60: 導入前後で同様の作業
C61: =IF('（別紙１）省力化計算シート'!J16="","",IF(OR('（別紙１）省力化計算シート'!N16="-",'（別紙１）省力化計算シート'!N16=0),'（別紙１）省力化計算シート'!J16&"分","("&'（別紙１）省力化計算シート'!J16-'（別紙１）省力化計算シート'!N16&"分→）"&'（別紙１）省力化計算シート'!J16&"分")) | G61: =IF('（別紙１）省力化計算シート'!J17="","",IF(OR('（別紙１）省力化計算シート'!N17="-",'（別紙１）省力化計算シート'!N17=0),'（別紙１）省力化計算シート'!J17&"分","("&'（別紙１）省力化計算シート'!J17-'（別紙１）省力化計算シート'!N17&"分→）"&'（別紙１）省力化計算シート'!J17&"分")) | K61: =IF('（別紙１）省力化計算シート'!J18="","",IF(OR('（別紙１）省力化計算シート'!N18="-",'（別紙１）省力化計算シート'!N18=0),'（別紙１）省力化計算シート'!J18&"分","("&'（別紙１）省力化計算シート'!J18-'（別紙１）省力化計算シート'!N18&"分→）"&'（別紙１）省力化計算シート'!J18&"分")) | O61: =IF('（別紙１）省力化計算シート'!J19="","",IF(OR('（別紙１）省力化計算シート'!N19="-",'（別紙１）省力化計算シート'!N19=0),'（別紙１）省力化計算シート'!J19&"分","("&'（別紙１）省力化計算シート'!J19-'（別紙１）省力化計算シート'!N19&"分→）"&'（別紙１）省力化計算シート'!J19&"分")) | S61: =IF('（別紙１）省力化計算シート'!J20="","",IF(OR('（別紙１）省力化計算シート'!N20="-",'（別紙１）省力化計算シート'!N20=0),'（別紙１）省力化計算シート'!J20&"分","("&'（別紙１）省力化計算シート'!J20-'（別紙１）省力化計算シート'!N20&"分→）"&'（別紙１）省力化計算シート'!J20&"分"))
X62: 作業内容の説明 入力欄
C67: ='（別紙１）省力化計算シート'!I21 -> 0 | E67: > | G67: ='（別紙１）省力化計算シート'!I22 -> 0 | I67: > | K67: ='（別紙１）省力化計算シート'!I23 -> 0 | M67: > | O67: ='（別紙１）省力化計算シート'!I24 -> 0 | Q67: > | S67: ='（別紙１）省力化計算シート'!I25 -> 0 | U67: >
C68: =IF('（別紙１）省力化計算シート'!J21="","",IF(OR('（別紙１）省力化計算シート'!N21="-",'（別紙１）省力化計算シート'!N21=0),'（別紙１）省力化計算シート'!J21&"分","("&'（別紙１）省力化計算シート'!J21-'（別紙１）省力化計算シート'!N21&"分→）"&'（別紙１）省力化計算シート'!J21&"分")) | G68: =IF('（別紙１）省力化計算シート'!J22="","",IF(OR('（別紙１）省力化計算シート'!N22="-",'（別紙１）省力化計算シート'!N22=0),'（別紙１）省力化計算シート'!J22&"分","("&'（別紙１）省力化計算シート'!J22-'（別紙１）省力化計算シート'!N22&"分→）"&'（別紙１）省力化計算シート'!J22&"分")) | K68: =IF('（別紙１）省力化計算シート'!J23="","",IF(OR('（別紙１）省力化計算シート'!N23="-",'（別紙１）省力化計算シート'!N23=0),'（別紙１）省力化計算シート'!J23&"分","("&'（別紙１）省力化計算シート'!J23-'（別紙１）省力化計算シート'!N23&"分→）"&'（別紙１）省力化計算シート'!J23&"分")) | O68: =IF('（別紙１）省力化計算シート'!J24="","",IF(OR('（別紙１）省力化計算シート'!N24="-",'（別紙１）省力化計算シート'!N24=0),'（別紙１）省力化計算シート'!J24&"分","("&'（別紙１）省力化計算シート'!J24-'（別紙１）省力化計算シート'!N24&"分→）"&'（別紙１）省力化計算シート'!J24&"分")) | S68: =IF('（別紙１）省力化計算シート'!J25="","",IF(OR('（別紙１）省力化計算シート'!N25="-",'（別紙１）省力化計算シート'!N25=0),'（別紙１）省力化計算シート'!J25&"分","("&'（別紙１）省力化計算シート'!J25-'（別紙１）省力化計算シート'!N25&"分→）"&'（別紙１）省力化計算シート'!J25&"分"))
C74: ='（別紙１）省力化計算シート'!I26 -> 0 | E74: > | G74: ='（別紙１）省力化計算シート'!I27 -> 0 | I74: > | K74: ='（別紙１）省力化計算シート'!I28 -> 0 | M74: > | O74: ='（別紙１）省力化計算シート'!I29 -> 0 | Q74: > | S74: ='（別紙１）省力化計算シート'!I30 -> 0 | U74: >
C75: =IF('（別紙１）省力化計算シート'!J26="","",IF(OR('（別紙１）省力化計算シート'!N26="-",'（別紙１）省力化計算シート'!N26=0),'（別紙１）省力化計算シート'!J26&"分","("&'（別紙１）省力化計算シート'!J26-'（別紙１）省力化計算シート'!N26&"分→）"&'（別紙１）省力化計算シート'!J26&"分")) | G75: =IF('（別紙１）省力化計算シート'!J27="","",IF(OR('（別紙１）省力化計算シート'!N27="-",'（別紙１）省力化計算シート'!N27=0),'（別紙１）省力化計算シート'!J27&"分","("&'（別紙１）省力化計算シート'!J27-'（別紙１）省力化計算シート'!N27&"分→）"&'（別紙１）省力化計算シート'!J27&"分")) | K75: =IF('（別紙１）省力化計算シート'!J28="","",IF(OR('（別紙１）省力化計算シート'!N28="-",'（別紙１）省力化計算シート'!N28=0),'（別紙１）省力化計算シート'!J28&"分","("&'（別紙１）省力化計算シート'!J28-'（別紙１）省力化計算シート'!N28&"分→）"&'（別紙１）省力化計算シート'!J28&"分")) | O75: =IF('（別紙１）省力化計算シート'!J29="","",IF(OR('（別紙１）省力化計算シート'!N29="-",'（別紙１）省力化計算シート'!N29=0),'（別紙１）省力化計算シート'!J29&"分","("&'（別紙１）省力化計算シート'!J29-'（別紙１）省力化計算シート'!N29&"分→）"&'（別紙１）省力化計算シート'!J29&"分")) | S75: =IF('（別紙１）省力化計算シート'!J30="","",IF(OR('（別紙１）省力化計算シート'!N30="-",'（別紙１）省力化計算シート'!N30=0),'（別紙１）省力化計算シート'!J30&"分","("&'（別紙１）省力化計算シート'!J30-'（別紙１）省力化計算シート'!N30&"分→）"&'（別紙１）省力化計算シート'!J30&"分"))
C81: ='（別紙１）省力化計算シート'!I31 -> 0 | E81: > | G81: ='（別紙１）省力化計算シート'!I32 -> 0 | I81: > | K81: ='（別紙１）省力化計算シート'!I33 -> 0 | M81: > | O81: ='（別紙１）省力化計算シート'!I34 -> 0 | Q81: > | S81: ='（別紙１）省力化計算シート'!I35 -> 0 | U81: >
C82: =IF('（別紙１）省力化計算シート'!J31="","",IF(OR('（別紙１）省力化計算シート'!N31="-",'（別紙１）省力化計算シート'!N31=0),'（別紙１）省力化計算シート'!J31&"分","("&'（別紙１）省力化計算シート'!J31-'（別紙１）省力化計算シート'!N31&"分→）"&'（別紙１）省力化計算シート'!J31&"分")) | G82: =IF('（別紙１）省力化計算シート'!J32="","",IF(OR('（別紙１）省力化計算シート'!N32="-",'（別紙１）省力化計算シート'!N32=0),'（別紙１）省力化計算シート'!J32&"分","("&'（別紙１）省力化計算シート'!J32-'（別紙１）省力化計算シート'!N32&"分→）"&'（別紙１）省力化計算シート'!J32&"分")) | K82: =IF('（別紙１）省力化計算シート'!J33="","",IF(OR('（別紙１）省力化計算シート'!N33="-",'（別紙１）省力化計算シート'!N33=0),'（別紙１）省力化計算シート'!J33&"分","("&'（別紙１）省力化計算シート'!J33-'（別紙１）省力化計算シート'!N33&"分→）"&'（別紙１）省力化計算シート'!J33&"分")) | O82: =IF('（別紙１）省力化計算シート'!J34="","",IF(OR('（別紙１）省力化計算シート'!N34="-",'（別紙１）省力化計算シート'!N34=0),'（別紙１）省力化計算シート'!J34&"分","("&'（別紙１）省力化計算シート'!J34-'（別紙１）省力化計算シート'!N34&"分→）"&'（別紙１）省力化計算シート'!J34&"分")) | S82: =IF('（別紙１）省力化計算シート'!J35="","",IF(OR('（別紙１）省力化計算シート'!N35="-",'（別紙１）省力化計算シート'!N35=0),'（別紙１）省力化計算シート'!J35&"分","("&'（別紙１）省力化計算シート'!J35-'（別紙１）省力化計算シート'!N35&"分→）"&'（別紙１）省力化計算シート'!J35&"分"))
C88: ='（別紙１）省力化計算シート'!I36 -> 0 | E88: > | G88: ='（別紙１）省力化計算シート'!I37 -> 0 | I88: > | K88: ='（別紙１）省力化計算シート'!I38 -> 0 | M88: > | O88: ='（別紙１）省力化計算シート'!I39 -> 0 | Q88: > | S88: ='（別紙１）省力化計算シート'!I40 -> 0
C89: =IF('（別紙１）省力化計算シート'!J36="","",IF(OR('（別紙１）省力化計算シート'!N36="-",'（別紙１）省力化計算シート'!N36=0),'（別紙１）省力化計算シート'!J36&"分","("&'（別紙１）省力化計算シート'!J36-'（別紙１）省力化計算シート'!N36&"分→）"&'（別紙１）省力化計算シート'!J36&"分")) | G89: =IF('（別紙１）省力化計算シート'!J37="","",IF(OR('（別紙１）省力化計算シート'!N37="-",'（別紙１）省力化計算シート'!N37=0),'（別紙１）省力化計算シート'!J37&"分","("&'（別紙１）省力化計算シート'!J37-'（別紙１）省力化計算シート'!N37&"分→）"&'（別紙１）省力化計算シート'!J37&"分")) | K89: =IF('（別紙１）省力化計算シート'!J38="","",IF(OR('（別紙１）省力化計算シート'!N38="-",'（別紙１）省力化計算シート'!N38=0),'（別紙１）省力化計算シート'!J38&"分","("&'（別紙１）省力化計算シート'!J38-'（別紙１）省力化計算シート'!N38&"分→）"&'（別紙１）省力化計算シート'!J38&"分")) | O89: =IF('（別紙１）省力化計算シート'!J39="","",IF(OR('（別紙１）省力化計算シート'!N39="-",'（別紙１）省力化計算シート'!N39=0),'（別紙１）省力化計算シート'!J39&"分","("&'（別紙１）省力化計算シート'!J39-'（別紙１）省力化計算シート'!N39&"分→）"&'（別紙１）省力化計算シート'!J39&"分")) | S89: =IF('（別紙１）省力化計算シート'!J40="","",IF(OR('（別紙１）省力化計算シート'!N40="-",'（別紙１）省力化計算シート'!N40=0),'（別紙１）省力化計算シート'!J40&"分","("&'（別紙１）省力化計算シート'!J40-'（別紙１）省力化計算シート'!N40&"分→）"&'（別紙１）省力化計算シート'!J40&"分"))
A93: =IF(COUNTA('（別紙１）省力化計算シート'!I26:I40)<>0,"← 非表示エリアに記載があります。[＋]をクリックして表示してください。[-]の場合は、すべて表示されています。","")

Sheet （別紙３）投資回収期間計算シート
B1: （別紙３）投資回収期間計算シート
B3: 投資回収期間 | C3: =IF(AND(O4=FALSE(),OR(C6="",H6="",J6="",L6="")),"",IF(AND(O4=TRUE(),OR(C6="",L6="")),"",IF(C6/(F6*H6*J6+L6)<=0,"",C6/(F6*H6*J6+L6)))) -> 0.17871437 | D3: 年 | O3: パラメータ（公開時に非表示）
O4: =FALSE() -> FALSE
C5: 投資総額（円） | F5: 削減工数(時間) | H5: 年間稼働日数（日） | J5: 人件費単価（円/時） | L5: 増加した付加価値額（円） | O5: =IF($O$4=TRUE(),"※新規事業の場合、削減工数（時間）は0と見なします。","※ 省力化計算シートより自動入力されます。") -> ※ 省力化計算シートより自動入力されます。
C6: 36950000 | D6: / | E6: （ | F6: =IF($O$4=TRUE(),0,'（別紙１）省力化計算シート'!D3-'（別紙１）省力化計算シート'!J3) -> 4 | G6: × | H6: =5*52 -> 260 | I6: × | J6: 1285 | K6: ＋ | L6: ='【参考書式】事業計画目標値算出シート（参考）'!I35-'【参考書式】事業計画目標値算出シート（参考）'!E35 -> 205418095 | M6: ）
C12: 【算定根拠】算定の根拠となる計算式等の説明があれば記載してください。
C13: 年間稼働日数＝5日/週×52週/年＝260日 人件費単価＝ケレン工程に従事する現場作業者の時間給1,285円／時 削減工数＝4時間／日（導入前8時間→導入後4時間） 増加した付加価値額＝504,317,324円（3年目）－298,899,229円（基準年度）＝205,418,095円 投資回収期間＝36,950,000円÷（4時間×260日×1,285円＋205,418,095円） 【参考】補助事業の直接効果のみで算定した場合：ケレン済み品の粗利改善62,438千円＋受託サービスの付加価値貢献26,600千円＝89,038千円 36,950,000円÷（1,336,400円＋89,038,000円）＝0.41年

Sheet 【参考書式】事業計画目標値算出シート（参考）
B1: ◆◆◆ 参考書式をご利用になる際のご注意点 ◆◆◆
B2: ・自動計算項目については、参考値となります。 | N2: （参考サイト：写真をタッチでリンクに飛びます）
B3: ・入力値(営業利益が大幅にマイナスの場合など)によっては、申請システムの計算値と異なる可能性があります。
B4: ・イメージがわかるよう入力値に数値をいれてありますが、上書きしてご活用ください。また、以下の機構ツールもぜひご活用ください。
B5: 「経営自己診断システム」「価格転嫁検討ツール」「儲かる経営キヅク君」→印刷枠外にリンクあります。
B6: ・申請システムへの入力は、この表の一部（緑字のセル）を転記していただくことになりますが、本事業における売上・収益計画等
B7: を立てるにあたっての参考にお使いください。（初めに直近決算書の実績数値を入れて、数値シミュレーションにもお使いください。）
B8: ・あくまでシステムに入力いただいた数値を正しいものとして審査します。（提出時に本シートは削除しなくて結構です。）
B9: 申請に係る要件の確認は、必ず申請システム上でご確認ください。
E11: 緑字 | F11: 申請システムへ転記する数字 | H11: 入力するとシミュレーションできます
E14: 青字 | F14: 成長率（自動計算）
E16: 黒字 | F16: 自動計算
B19: 【参考書式】事業計画目標値算出シート
B21: 労働生産性の算定シート
E22: 基準年度 | G22: 1 | H22: 2 | I22: 3 | J22: 4 | K22: 5
E23: 直近の決算年月 | G23: 年目計画 | H23: 年目計画 | I23: 年目計画 | J23: 年目計画 | K23: 年目計画
E24: 2025年10月期 | G24: 2028年10月期 | H24: 2029年10月期 | I24: 2030年10月期 | J24: 2031年10月期 | K24: 2032年10月期
B26: 売上高 | E26: 3854560200 | G26: 4506131527 | H26: 4704072736 | I26: 4910921299 | J26: 5127078047 | K26: 5352961849
B27: 売上原価 | E27: 3182783781 | G27: 3632085034 | H27: 3795528861 | I27: 3966327660 | J27: 4144812404 | K27: 4331328962
B28: 売上総利益 | E28: =E26-E27 -> 671776419 | G28: =G26-G27 -> 874046493 | H28: =H26-H27 -> 908543875 | I28: =I26-I27 -> 944593639 | J28: =J26-J27 -> 982265643 | K28: =K26-K27 -> 1021632887
B29: 販売費及び一般管理費 | E29: 515737893 | G29: 585880943 | H29: 598780842 | I29: 612030608 | J29: 625641116 | K29: 639623397
B30: ① 営業利益 | E30: =E28-E29 -> 156038526 | G30: =G28-G29 -> 288165550 | H30: =H28-H29 -> 309763033 | I30: =I28-I29 -> 332563031 | J30: =J28-J29 -> 356624527 | K30: =K28-K29 -> 382009490
B31: ② 人件費 （注１） | E31: =57600000+32359082+8349364+8900000+10616167+2331297 -> 120155910 | G31: 139339700 | H31: 142200900 | I31: 145161000 | J31: 148224600 | K31: 151396300
B32: ③ 減価償却費 | E32: =E33+E34 -> 22704796 | G32: =G33+G34 -> 26593296 | H32: =H33+H34 -> 26593296 | I32: =I33+I34 -> 26593296 | J32: =J33+J34 -> 26593296 | K32: =K33+K34 -> 26593296
B33: （内訳）既存設備の減価償却費 | E33: 22704796 | G33: 22704796 | H33: 22704796 | I33: 22704796 | J33: 22704796 | K33: 22704796
B34: 本補助金で導入する設備の減価償却費 | G34: 3888500 | H34: 3888500 | I34: 3888500 | J34: 3888500 | K34: 3888500
B35: ④付加価値額（①+②+③） | E35: =E30+E31+E32 -> 298899232 | G35: =G30+G31+G32 -> 454098546 | H35: =H30+H31+H32 -> 478557229 | I35: =I30+I31+I32 -> 504317327 | J35: =J30+J31+J32 -> 531442423 | K35: =K30+K31+K32 -> 559999086
B36: 付加価値額の年平均成長率（％） | G36: =ROUNDDOWN(((G35/$E$35)^(1/G22)-1)*100,2) -> 51.92 | H36: =ROUNDDOWN(((H35/$E$35)^(1/H22)-1)*100,2) -> 26.53 | I36: =ROUNDDOWN(((I35/$E$35)^(1/I22)-1)*100,2) -> 19.04 | J36: =ROUNDDOWN(((J35/$E$35)^(1/J22)-1)*100,2) -> 15.47 | K36: =ROUNDDOWN(((K35/$E$35)^(1/K22)-1)*100,2) -> 13.37
B37: ⑤労働者数のうち役員数（人） | E37: 2 | G37: 2 | H37: 2 | I37: 2 | J37: 2 | K37: 2
B38: ⑥労働者数のうち常勤従業員数（人） （注２） | E38: 10 | G38: 15 | H38: 15 | I38: 15 | J38: 15 | K38: 15
B39: 労働生産性(＝１人あたり付加価値額)（④÷(⑤＋⑥)） | E39: =IF(E35<0,ROUNDUP((E35/(E37+E38)),2),ROUNDDOWN((E35/(E37+E38)),2)) -> 24908269 | G39: =IF(G35<0,ROUNDUP((G35/(G37+G38)),2),ROUNDDOWN((G35/(G37+G38)),2)) -> 26711679 | H39: =IF(H35<0,ROUNDUP((H35/(H37+H38)),2),ROUNDDOWN((H35/(H37+H38)),2)) -> 28150425 | I39: =IF(I35<0,ROUNDUP((I35/(I37+I38)),2),ROUNDDOWN((I35/(I37+I38)),2)) -> 29665725 | J39: =IF(J35<0,ROUNDUP((J35/(J37+J38)),2),ROUNDDOWN((J35/(J37+J38)),2)) -> 31261319 | K39: =IF(K35<0,ROUNDUP((K35/(K37+K38)),2),ROUNDDOWN((K35/(K37+K38)),2)) -> 32941123
B40: 労働生産性の目標値 （年平均成長率４％ずつ上げる場合） | G40: =IFERROR(IF($E$35>=0,ROUNDUP(((ABS($E$35)*1.04^G22-(ABS($E$35)))+$E$35)/($E$37+$E$38),2),ROUNDDOWN(((ABS($E$35)*1.04^G22-(ABS($E$35)))+$E$35)/($E$37+$E$38),2)),0) -> 25904600 | H40: =IFERROR(IF($E$35>=0,ROUNDUP(((ABS($E$35)*1.04^H22-(ABS($E$35)))+$E$35)/($E$37+$E$38),2),ROUNDDOWN(((ABS($E$35)*1.04^H22-(ABS($E$35)))+$E$35)/($E$37+$E$38),2)),0) -> 26940784 | I40: =IFERROR(IF($E$35>=0,ROUNDUP(((ABS($E$35)*1.04^I22-(ABS($E$35)))+$E$35)/($E$37+$E$38),2),ROUNDDOWN(((ABS($E$35)*1.04^I22-(ABS($E$35)))+$E$35)/($E$37+$E$38),2)),0) -> 28018415 | J40: =IFERROR(IF($E$35>=0,ROUNDUP(((ABS($E$35)*1.04^J22-(ABS($E$35)))+$E$35)/($E$37+$E$38),2),ROUNDDOWN(((ABS($E$35)*1.04^J22-(ABS($E$35)))+$E$35)/($E$37+$E$38),2)),0) -> 29139152 | K40: =IFERROR(IF($E$35>=0,ROUNDUP(((ABS($E$35)*1.04^K22-(ABS($E$35)))+$E$35)/($E$37+$E$38),2),ROUNDDOWN(((ABS($E$35)*1.04^K22-(ABS($E$35)))+$E$35)/($E$37+$E$38),2)),0) -> 30304718
B41: 労働生産性の年平均成長率（％）（注３） | G41: =ROUNDDOWN(((G39/$E$39)^(1/G22)-1)*100,2) -> 7.24 | H41: =ROUNDDOWN(((H39/$E$39)^(1/H22)-1)*100,2) -> 6.3 | I41: =ROUNDDOWN(((I39/$E$39)^(1/I22)-1)*100,2) -> 5.99 | J41: =ROUNDDOWN(((J39/$E$39)^(1/J22)-1)*100,2) -> 5.84 | K41: =ROUNDDOWN(((K39/$E$39)^(1/K22)-1)*100,2) -> 5.74
B43: １人当たり給与支給総額の算定シート
B44: ⑦全月分の給与等の支給を受けた従業員の給与支給総額 （注４） | E44: 36625814 | G44: 71078000 | H44: 73566000 | I44: 76140000 | J44: 78804000 | K44: 81562000
B45: ⑧全月分の給与等の支給を受けた従業員数（人）（注４） | E45: 8 | G45: 15 | H45: 15 | I45: 15 | J45: 15 | K45: 15
B46: １人当たり給与支給総額 | C46: （⑦÷⑧） | E46: =ROUNDDOWN(E44/E45,2) -> 4578226.8 | G46: =ROUNDDOWN(G44/G45,2) -> 4738533.3 | H46: =ROUNDDOWN(H44/H45,2) -> 4904400 | I46: =ROUNDDOWN(I44/I45,2) -> 5076000 | J46: =ROUNDDOWN(J44/J45,2) -> 5253600 | K46: =ROUNDDOWN(K44/K45,2) -> 5437466.7
B47: 従業員1人当たり給与支給総額の目標値 | C47: 【特例無し】3.5％ | G47: =ROUNDUP(($E$44+(ABS($E$44)*1.035^G22-ABS($E$44)))/($E$45),0) -> 4738465 | H47: =ROUNDUP(($E$44+(ABS($E$44)*1.035^H22-ABS($E$44)))/($E$45),0) -> 4904311 | I47: =ROUNDUP(($E$44+(ABS($E$44)*1.035^I22-ABS($E$44)))/($E$45),0) -> 5075962 | J47: =ROUNDUP(($E$44+(ABS($E$44)*1.035^J22-ABS($E$44)))/($E$45),0) -> 5253621 | K47: =ROUNDUP(($E$44+(ABS($E$44)*1.035^K22-ABS($E$44)))/($E$45),0) -> 5437498
C48: 【大幅な賃上げ特例】6.0％ | G48: =ROUNDUP(($E$44+(ABS($E$44)*1.06^G22-ABS($E$44)))/($E$45),0) -> 4852921 | H48: =ROUNDUP(($E$44+(ABS($E$44)*1.06^H22-ABS($E$44)))/($E$45),0) -> 5144096 | I48: =ROUNDUP(($E$44+(ABS($E$44)*1.06^I22-ABS($E$44)))/($E$45),0) -> 5452742 | J48: =ROUNDUP(($E$44+(ABS($E$44)*1.06^J22-ABS($E$44)))/($E$45),0) -> 5779906 | K48: =ROUNDUP(($E$44+(ABS($E$44)*1.06^K22-ABS($E$44)))/($E$45),0) -> 6126701
B49: 従業員１人当たり給与支給総額の年平均成長率（％） （注３） | G49: =IFERROR(IF(G$46>=$E$46,ROUNDDOWN(((G46/$E$46)^(1/G22)-1)*100,2),ROUNDUP(((G46/$E$46)^(1/G22)-1)*100,2)),0) -> 3.5 | H49: =IFERROR(IF(H$46>=$E$46,ROUNDDOWN(((H46/$E$46)^(1/H22)-1)*100,2),ROUNDUP(((H46/$E$46)^(1/H22)-1)*100,2)),0) -> 3.5 | I49: =IFERROR(IF(I$46>=$E$46,ROUNDDOWN(((I46/$E$46)^(1/I22)-1)*100,2),ROUNDUP(((I46/$E$46)^(1/I22)-1)*100,2)),0) -> 3.5 | J49: =IFERROR(IF(J$46>=$E$46,ROUNDDOWN(((J46/$E$46)^(1/J22)-1)*100,2),ROUNDUP(((J46/$E$46)^(1/J22)-1)*100,2)),0) -> 3.49 | K49: =IFERROR(IF(K$46>=$E$46,ROUNDDOWN(((K46/$E$46)^(1/K22)-1)*100,2),ROUNDUP(((K46/$E$46)^(1/K22)-1)*100,2)),0) -> 3.49
...

Sheet 【参考書式】達成すべき目標値の算出ツール（参考）
C1: (参考)
D3: 基準年 | E3: 1 | F3: 2 | G3: 3 | H3: 4 | I3: 5
C4: 増加率 | E4: 0.02 | F4: =(1+$E4)^$F3-1 -> 0.0404 | G4: =(1+$E4)^G3-1 -> 0.061208 | H4: =(1+$E4)^H3-1 -> 0.08243216 | I4: =(1+$E4)^I3-1 -> 0.1040808
D5: 1000 | E5: =$D5*((1+$E4)^E3) -> 1020 | F5: =$D5*((1+$E4)^F3) -> 1040.4 | G5: =$D5*((1+$E4)^G3) -> 1061.208 | H5: =$D5*((1+$E4)^H3) -> 1082.4322 | I5: =$D5*((1+$E4)^I3) -> 1104.0808
E6: 0.04 | F6: =(1+$E6)^F3-1 -> 0.0816 | G6: =(1+$E6)^G3-1 -> 0.124864 | H6: =(1+$E6)^H3-1 -> 0.16985856 | I6: =(1+$E6)^I3-1 -> 0.2166529
E7: 0.05 | F7: =(1+$E7)^F3-1 -> 0.1025 | G7: =(1+$E7)^G3-1 -> 0.157625 | H7: =(1+$E7)^H3-1 -> 0.21550625 | I7: =(1+$E7)^I3-1 -> 0.27628156
E8: 0.06 | F8: =(1+$E8)^F3-1 -> 0.1236 | G8: =(1+$E8)^G3-1 -> 0.191016 | H8: =(1+$E8)^H3-1 -> 0.26247696 | I8: =(1+$E8)^I3-1 -> 0.33822558
E9: 0.07 | F9: =(1+$E9)^F3-1 -> 0.1449 | G9: =(1+$E9)^G3-1 -> 0.225043 | H9: =(1+$E9)^H3-1 -> 0.31079601 | I9: =(1+$E9)^I3-1 -> 0.40255173
E10: 0.08 | F10: =(1+$E10)^F3-1 -> 0.1664 | G10: =(1+$E10)^G3-1 -> 0.259712 | H10: =(1+$E10)^H3-1 -> 0.36048896 | I10: =(1+$E10)^I3-1 -> 0.46932808
E11: 0.09 | F11: =(1+$E11)^F3-1 -> 0.1881 | G11: =(1+$E11)^G3-1 -> 0.295029 | H11: =(1+$E11)^H3-1 -> 0.41158161 | I11: =(1+$E11)^I3-1 -> 0.53862395
D13: 基準年 | E13: １年目 | F13: ２年目 | G13: ３年目 | H13: ４年目 | I13: ５年目
C14: 増加率 | E14: 0.035 | F14: =(1+$E14)^F3-1 -> 0.071225 | G14: =(1+$E14)^G3-1 -> 0.10871788 | H14: =(1+$E14)^H3-1 -> 0.147523 | I14: =(1+$E14)^I3-1 -> 0.18768631
C15: 目標値 | D15: 4578226.8 | E15: =ROUNDUP($D$15*((1+$E14)^E3),3) -> 4738464.7 | F15: =$D$15*((1+$E14)^F3) -> 4904311 | G15: =$D15*((1+$E14)^G3) -> 5075961.8 | H15: =$D15*((1+$E14)^H3) -> 5253620.5 | I15: =$D15*((1+$E14)^I3) -> 5437497.2
C16: 年平均成長率 | E16: =ROUNDDOWN(((E15/$D$15)^(1/E3)-1),5) -> 0.035 | F16: =ROUNDDOWN(((F15/$D$15)^(1/F3)-1),5) -> 0.03499 | G16: =ROUNDDOWN(((G15/$D$15)^(1/G3)-1),5) -> 0.03499 | H16: =ROUNDDOWN(((H15/$D$15)^(1/H3)-1),5) -> 0.03499 | I16: =ROUNDDOWN(((I15/$D$15)^(1/I3)-1),5) -> 0.03499
